<mujoco>  
    <option gravity="0 0 -9.8" />  
    <worldbody>  
        <light diffuse=".5 .5 .5" pos="0 0 3" dir="0 0 -1"/>  
        <geom type="plane" size="5 5 0.1" rgba=".9 .9 .9 1"/>  
        <body name="box" pos="0 0 0.2" euler="0 90 0">  
            <joint type="free"/>  
            <geom type="box" size=".05 .2 .5" rgba=".9 .9 0 1"/>  
            <site name="marker" pos="0 0 0" size="0.1" />  
            <body name="left_tire" pos="0 0.3 -0.5" euler="90 0 0">  
                <joint name="left_wheel" type="hinge" axis="0 0 -1" />  
                <geom type="cylinder" size=".2 .05" rgba="0 .9 0 1"/>  
            </body>  
            <body name="right_tire" pos="0 -0.3 -0.5" euler="90 0 0">  
                <joint name="right_wheel" type="hinge" axis="0 0 -1" />  
                <geom type="cylinder" size=".2 .05" rgba="0 .9 0 1"/>  
            </body>  
            <camera name="my_camera" pos="-2 0 1" xyaxes="0 -1 0 0 0 1" />
        </body>  
    </worldbody>  
    <sensor>  
        <framepos objtype="site" objname="marker" />  
    </sensor>  
    <actuator>  
        <velocity name="left-velocity-servo" joint="left_wheel" kv="50" />  
        <velocity name="right-velocity-servo" joint="right_wheel" kv="50" />  
    </actuator>  
</mujoco>